Workbook

Sheet อัตราค่าคอม
A1: EasyCRM — อัตราค่าคอมมิชชั่น Sales Executive
A2: แก้ตัวเลขในตารางนี้ได้เลย ชีต 'คำนวณรายเดือน' จะดึงไปคำนวณอัตโนมัติ
A4: แพ็กเกจ | B4: ราคา/ปี (ไม่รวม VAT) | C4: % ค่าคอม | D4: ค่าคอม/ดีล (ใหม่) | E4: % ค่าคอม Renewal | F4: ค่าคอม/ดีล (ต่ออายุ)
A5: Starter | B5: 15588 | C5: 0.1 | D5: =B5*C5 | E5: 0.05 | F5: =B5*E5
A6: Plus | B6: 23988 | C6: 0.12 | D6: =B6*C6 | E6: 0.06 | F6: =B6*E6
A7: Premium | B7: 35988 | C7: 0.15 | D7: =B7*C7 | E7: 0.075 | F7: =B7*E7
A8: Enterprise | C8: 0.1 | D8: =B8*C8 | E8: 0.05 | F8: =B8*E8
B9: กรอกตามดีลจริง
A11: หมายเหตุ
A12: • ราคาที่ใช้คำนวณค่าคอม = ราคาก่อน VAT 7%
A13: • Renewal (ต่ออายุ) ได้ครึ่งหนึ่งของค่าคอมดีลใหม่ — ปรับได้ในคอลัมน์ E
A14: • Enterprise: ราคาตามสัญญา → กรอกราคาดีลในชีต 'คำนวณรายเดือน' โดยตรง
A15: • ค่าคอมจ่ายเมื่อ: ลูกค้าชำระเงินครบ + ส่งมอบระบบ (Phase 5 เสร็จ)
A16: • เงื่อนไขการยกเลิก: ลูกค้ายกเลิก/refund ภายใน 30 วัน → หักค่าคอมคืน

Sheet คำนวณรายเดือน
A1: บันทึกดีลรายเดือน — ค่าคอมจะคำนวณอัตโนมัติ
A2: กรอก: วันที่ปิดดีล / Sales / ลูกค้า / แพ็กเกจ / ประเภท (ใหม่/ต่ออายุ) / ราคา (ถ้า Enterprise) / สถานะจ่าย
A4: วันที่ปิดดีล | B4: Sales | C4: ลูกค้า | D4: แพ็กเกจ | E4: ประเภท | F4: ราคาดีล (฿) | G4: % ค่าคอม | H4: ค่าคอม (฿) | I4: สถานะจ่ายค่าคอม
G5: =IF(D5="","",IF(E5="ต่ออายุ",IFERROR(VLOOKUP(D5,อัตราค่าคอม!A5:E8,5,FALSE),0),IFERROR(VLOOKUP(D5,อัตราค่าคอม!A5:C8,3,FALSE),0))) | H5: =IF(D5="","",IF(D5="Enterprise",IFERROR(F5*G5,0),IFERROR(VLOOKUP(D5,อัตราค่าคอม!A5:B8,2,FALSE)*G5,0)))
G6: =IF(D6="","",IF(E6="ต่ออายุ",IFERROR(VLOOKUP(D6,อัตราค่าคอม!A5:E8,5,FALSE),0),IFERROR(VLOOKUP(D6,อัตราค่าคอม!A5:C8,3,FALSE),0))) | H6: =IF(D6="","",IF(D6="Enterprise",IFERROR(F6*G6,0),IFERROR(VLOOKUP(D6,อัตราค่าคอม!A5:B8,2,FALSE)*G6,0)))
G7: =IF(D7="","",IF(E7="ต่ออายุ",IFERROR(VLOOKUP(D7,อัตราค่าคอม!A5:E8,5,FALSE),0),IFERROR(VLOOKUP(D7,อัตราค่าคอม!A5:C8,3,FALSE),0))) | H7: =IF(D7="","",IF(D7="Enterprise",IFERROR(F7*G7,0),IFERROR(VLOOKUP(D7,อัตราค่าคอม!A5:B8,2,FALSE)*G7,0)))
G8: =IF(D8="","",IF(E8="ต่ออายุ",IFERROR(VLOOKUP(D8,อัตราค่าคอม!A5:E8,5,FALSE),0),IFERROR(VLOOKUP(D8,อัตราค่าคอม!A5:C8,3,FALSE),0))) | H8: =IF(D8="","",IF(D8="Enterprise",IFERROR(F8*G8,0),IFERROR(VLOOKUP(D8,อัตราค่าคอม!A5:B8,2,FALSE)*G8,0)))
G9: =IF(D9="","",IF(E9="ต่ออายุ",IFERROR(VLOOKUP(D9,อัตราค่าคอม!A5:E8,5,FALSE),0),IFERROR(VLOOKUP(D9,อัตราค่าคอม!A5:C8,3,FALSE),0))) | H9: =IF(D9="","",IF(D9="Enterprise",IFERROR(F9*G9,0),IFERROR(VLOOKUP(D9,อัตราค่าคอม!A5:B8,2,FALSE)*G9,0)))
G10: =IF(D10="","",IF(E10="ต่ออายุ",IFERROR(VLOOKUP(D10,อัตราค่าคอม!A5:E8,5,FALSE),0),IFERROR(VLOOKUP(D10,อัตราค่าคอม!A5:C8,3,FALSE),0))) | H10: =IF(D10="","",IF(D10="Enterprise",IFERROR(F10*G10,0),IFERROR(VLOOKUP(D10,อัตราค่าคอม!A5:B8,2,FALSE)*G10,0)))
G11: =IF(D11="","",IF(E11="ต่ออายุ",IFERROR(VLOOKUP(D11,อัตราค่าคอม!A5:E8,5,FALSE),0),IFERROR(VLOOKUP(D11,อัตราค่าคอม!A5:C8,3,FALSE),0))) | H11: =IF(D11="","",IF(D11="Enterprise",IFERROR(F11*G11,0),IFERROR(VLOOKUP(D11,อัตราค่าคอม!A5:B8,2,FALSE)*G11,0)))
G12: =IF(D12="","",IF(E12="ต่ออายุ",IFERROR(VLOOKUP(D12,อัตราค่าคอม!A5:E8,5,FALSE),0),IFERROR(VLOOKUP(D12,อัตราค่าคอม!A5:C8,3,FALSE),0))) | H12: =IF(D12="","",IF(D12="Enterprise",IFERROR(F12*G12,0),IFERROR(VLOOKUP(D12,อัตราค่าคอม!A5:B8,2,FALSE)*G12,0)))
G13: =IF(D13="","",IF(E13="ต่ออายุ",IFERROR(VLOOKUP(D13,อัตราค่าคอม!A5:E8,5,FALSE),0),IFERROR(VLOOKUP(D13,อัตราค่าคอม!A5:C8,3,FALSE),0))) | H13: =IF(D13="","",IF(D13="Enterprise",IFERROR(F13*G13,0),IFERROR(VLOOKUP(D13,อัตราค่าคอม!A5:B8,2,FALSE)*G13,0)))
G14: =IF(D14="","",IF(E14="ต่ออายุ",IFERROR(VLOOKUP(D14,อัตราค่าคอม!A5:E8,5,FALSE),0),IFERROR(VLOOKUP(D14,อัตราค่าคอม!A5:C8,3,FALSE),0))) | H14: =IF(D14="","",IF(D14="Enterprise",IFERROR(F14*G14,0),IFERROR(VLOOKUP(D14,อัตราค่าคอม!A5:B8,2,FALSE)*G14,0)))
G15: =IF(D15="","",IF(E15="ต่ออายุ",IFERROR(VLOOKUP(D15,อัตราค่าคอม!A5:E8,5,FALSE),0),IFERROR(VLOOKUP(D15,อัตราค่าคอม!A5:C8,3,FALSE),0))) | H15: =IF(D15="","",IF(D15="Enterprise",IFERROR(F15*G15,0),IFERROR(VLOOKUP(D15,อัตราค่าคอม!A5:B8,2,FALSE)*G15,0)))
G16: =IF(D16="","",IF(E16="ต่ออายุ",IFERROR(VLOOKUP(D16,อัตราค่าคอม!A5:E8,5,FALSE),0),IFERROR(VLOOKUP(D16,อัตราค่าคอม!A5:C8,3,FALSE),0))) | H16: =IF(D16="","",IF(D16="Enterprise",IFERROR(F16*G16,0),IFERROR(VLOOKUP(D16,อัตราค่าคอม!A5:B8,2,FALSE)*G16,0)))
G17: =IF(D17="","",IF(E17="ต่ออายุ",IFERROR(VLOOKUP(D17,อัตราค่าคอม!A5:E8,5,FALSE),0),IFERROR(VLOOKUP(D17,อัตราค่าคอม!A5:C8,3,FALSE),0))) | H17: =IF(D17="","",IF(D17="Enterprise",IFERROR(F17*G17,0),IFERROR(VLOOKUP(D17,อัตราค่าคอม!A5:B8,2,FALSE)*G17,0)))
G18: =IF(D18="","",IF(E18="ต่ออายุ",IFERROR(VLOOKUP(D18,อัตราค่าคอม!A5:E8,5,FALSE),0),IFERROR(VLOOKUP(D18,อัตราค่าคอม!A5:C8,3,FALSE),0))) | H18: =IF(D18="","",IF(D18="Enterprise",IFERROR(F18*G18,0),IFERROR(VLOOKUP(D18,อัตราค่าคอม!A5:B8,2,FALSE)*G18,0)))
G19: =IF(D19="","",IF(E19="ต่ออายุ",IFERROR(VLOOKUP(D19,อัตราค่าคอม!A5:E8,5,FALSE),0),IFERROR(VLOOKUP(D19,อัตราค่าคอม!A5:C8,3,FALSE),0))) | H19: =IF(D19="","",IF(D19="Enterprise",IFERROR(F19*G19,0),IFERROR(VLOOKUP(D19,อัตราค่าคอม!A5:B8,2,FALSE)*G19,0)))
G20: =IF(D20="","",IF(E20="ต่ออายุ",IFERROR(VLOOKUP(D20,อัตราค่าคอม!A5:E8,5,FALSE),0),IFERROR(VLOOKUP(D20,อัตราค่าคอม!A5:C8,3,FALSE),0))) | H20: =IF(D20="","",IF(D20="Enterprise",IFERROR(F20*G20,0),IFERROR(VLOOKUP(D20,อัตราค่าคอม!A5:B8,2,FALSE)*G20,0)))
G21: =IF(D21="","",IF(E21="ต่ออายุ",IFERROR(VLOOKUP(D21,อัตราค่าคอม!A5:E8,5,FALSE),0),IFERROR(VLOOKUP(D21,อัตราค่าคอม!A5:C8,3,FALSE),0))) | H21: =IF(D21="","",IF(D21="Enterprise",IFERROR(F21*G21,0),IFERROR(VLOOKUP(D21,อัตราค่าคอม!A5:B8,2,FALSE)*G21,0)))
G22: =IF(D22="","",IF(E22="ต่ออายุ",IFERROR(VLOOKUP(D22,อัตราค่าคอม!A5:E8,5,FALSE),0),IFERROR(VLOOKUP(D22,อัตราค่าคอม!A5:C8,3,FALSE),0))) | H22: =IF(D22="","",IF(D22="Enterprise",IFERROR(F22*G22,0),IFERROR(VLOOKUP(D22,อัตราค่าคอม!A5:B8,2,FALSE)*G22,0)))
G23: =IF(D23="","",IF(E23="ต่ออายุ",IFERROR(VLOOKUP(D23,อัตราค่าคอม!A5:E8,5,FALSE),0),IFERROR(VLOOKUP(D23,อัตราค่าคอม!A5:C8,3,FALSE),0))) | H23: =IF(D23="","",IF(D23="Enterprise",IFERROR(F23*G23,0),IFERROR(VLOOKUP(D23,อัตราค่าคอม!A5:B8,2,FALSE)*G23,0)))
G24: =IF(D24="","",IF(E24="ต่ออายุ",IFERROR(VLOOKUP(D24,อัตราค่าคอม!A5:E8,5,FALSE),0),IFERROR(VLOOKUP(D24,อัตราค่าคอม!A5:C8,3,FALSE),0))) | H24: =IF(D24="","",IF(D24="Enterprise",IFERROR(F24*G24,0),IFERROR(VLOOKUP(D24,อัตราค่าคอม!A5:B8,2,FALSE)*G24,0)))
G25: =IF(D25="","",IF(E25="ต่ออายุ",IFERROR(VLOOKUP(D25,อัตราค่าคอม!A5:E8,5,FALSE),0),IFERROR(VLOOKUP(D25,อัตราค่าคอม!A5:C8,3,FALSE),0))) | H25: =IF(D25="","",IF(D25="Enterprise",IFERROR(F25*G25,0),IFERROR(VLOOKUP(D25,อัตราค่าคอม!A5:B8,2,FALSE)*G25,0)))
G26: =IF(D26="","",IF(E26="ต่ออายุ",IFERROR(VLOOKUP(D26,อัตราค่าคอม!A5:E8,5,FALSE),0),IFERROR(VLOOKUP(D26,อัตราค่าคอม!A5:C8,3,FALSE),0))) | H26: =IF(D26="","",IF(D26="Enterprise",IFERROR(F26*G26,0),IFERROR(VLOOKUP(D26,อัตราค่าคอม!A5:B8,2,FALSE)*G26,0)))
G27: =IF(D27="","",IF(E27="ต่ออายุ",IFERROR(VLOOKUP(D27,อัตราค่าคอม!A5:E8,5,FALSE),0),IFERROR(VLOOKUP(D27,อัตราค่าคอม!A5:C8,3,FALSE),0))) | H27: =IF(D27="","",IF(D27="Enterprise",IFERROR(F27*G27,0),IFERROR(VLOOKUP(D27,อัตราค่าคอม!A5:B8,2,FALSE)*G27,0)))
G28: =IF(D28="","",IF(E28="ต่ออายุ",IFERROR(VLOOKUP(D28,อัตราค่าคอม!A5:E8,5,FALSE),0),IFERROR(VLOOKUP(D28,อัตราค่าคอม!A5:C8,3,FALSE),0))) | H28: =IF(D28="","",IF(D28="Enterprise",IFERROR(F28*G28,0),IFERROR(VLOOKUP(D28,อัตราค่าคอม!A5:B8,2,FALSE)*G28,0)))
G29: =IF(D29="","",IF(E29="ต่ออายุ",IFERROR(VLOOKUP(D29,อัตราค่าคอม!A5:E8,5,FALSE),0),IFERROR(VLOOKUP(D29,อัตราค่าคอม!A5:C8,3,FALSE),0))) | H29: =IF(D29="","",IF(D29="Enterprise",IFERROR(F29*G29,0),IFERROR(VLOOKUP(D29,อัตราค่าคอม!A5:B8,2,FALSE)*G29,0)))
G30: =IF(D30="","",IF(E30="ต่ออายุ",IFERROR(VLOOKUP(D30,อัตราค่าคอม!A5:E8,5,FALSE),0),IFERROR(VLOOKUP(D30,อัตราค่าคอม!A5:C8,3,FALSE),0))) | H30: =IF(D30="","",IF(D30="Enterprise",IFERROR(F30*G30,0),IFERROR(VLOOKUP(D30,อัตราค่าคอม!A5:B8,2,FALSE)*G30,0)))
G31: =IF(D31="","",IF(E31="ต่ออายุ",IFERROR(VLOOKUP(D31,อัตราค่าคอม!A5:E8,5,FALSE),0),IFERROR(VLOOKUP(D31,อัตราค่าคอม!A5:C8,3,FALSE),0))) | H31: =IF(D31="","",IF(D31="Enterprise",IFERROR(F31*G31,0),IFERROR(VLOOKUP(D31,อัตราค่าคอม!A5:B8,2,FALSE)*G31,0)))
G32: =IF(D32="","",IF(E32="ต่ออายุ",IFERROR(VLOOKUP(D32,อัตราค่าคอม!A5:E8,5,FALSE),0),IFERROR(VLOOKUP(D32,อัตราค่าคอม!A5:C8,3,FALSE),0))) | H32: =IF(D32="","",IF(D32="Enterprise",IFERROR(F32*G32,0),IFERROR(VLOOKUP(D32,อัตราค่าคอม!A5:B8,2,FALSE)*G32,0)))
G33: =IF(D33="","",IF(E33="ต่ออายุ",IFERROR(VLOOKUP(D33,อัตราค่าคอม!A5:E8,5,FALSE),0),IFERROR(VLOOKUP(D33,อัตราค่าคอม!A5:C8,3,FALSE),0))) | H33: =IF(D33="","",IF(D33="Enterprise",IFERROR(F33*G33,0),IFERROR(VLOOKUP(D33,อัตราค่าคอม!A5:B8,2,FALSE)*G33,0)))
G34: =IF(D34="","",IF(E34="ต่ออายุ",IFERROR(VLOOKUP(D34,อัตราค่าคอม!A5:E8,5,FALSE),0),IFERROR(VLOOKUP(D34,อัตราค่าคอม!A5:C8,3,FALSE),0))) | H34: =IF(D34="","",IF(D34="Enterprise",IFERROR(F34*G34,0),IFERROR(VLOOKUP(D34,อัตราค่าคอม!A5:B8,2,FALSE)*G34,0)))
G35: =IF(D35="","",IF(E35="ต่ออายุ",IFERROR(VLOOKUP(D35,อัตราค่าคอม!A5:E8,5,FALSE),0),IFERROR(VLOOKUP(D35,อัตราค่าคอม!A5:C8,3,FALSE),0))) | H35: =IF(D35="","",IF(D35="Enterprise",IFERROR(F35*G35,0),IFERROR(VLOOKUP(D35,อัตราค่าคอม!A5:B8,2,FALSE)*G35,0)))
G36: =IF(D36="","",IF(E36="ต่ออายุ",IFERROR(VLOOKUP(D36,อัตราค่าคอม!A5:E8,5,FALSE),0),IFERROR(VLOOKUP(D36,อัตราค่าคอม!A5:C8,3,FALSE),0))) | H36: =IF(D36="","",IF(D36="Enterprise",IFERROR(F36*G36,0),IFERROR(VLOOKUP(D36,อัตราค่าคอม!A5:B8,2,FALSE)*G36,0)))
G37: =IF(D37="","",IF(E37="ต่ออายุ",IFERROR(VLOOKUP(D37,อัตราค่าคอม!A5:E8,5,FALSE),0),IFERROR(VLOOKUP(D37,อัตราค่าคอม!A5:C8,3,FALSE),0))) | H37: =IF(D37="","",IF(D37="Enterprise",IFERROR(F37*G37,0),IFERROR(VLOOKUP(D37,อัตราค่าคอม!A5:B8,2,FALSE)*G37,0)))
G38: =IF(D38="","",IF(E38="ต่ออายุ",IFERROR(VLOOKUP(D38,อัตราค่าคอม!A5:E8,5,FALSE),0),IFERROR(VLOOKUP(D38,อัตราค่าคอม!A5:C8,3,FALSE),0))) | H38: =IF(D38="","",IF(D38="Enterprise",IFERROR(F38*G38,0),IFERROR(VLOOKUP(D38,อัตราค่าคอม!A5:B8,2,FALSE)*G38,0)))
G39: =IF(D39="","",IF(E39="ต่ออายุ",IFERROR(VLOOKUP(D39,อัตราค่าคอม!A5:E8,5,FALSE),0),IFERROR(VLOOKUP(D39,อัตราค่าคอม!A5:C8,3,FALSE),0))) | H39: =IF(D39="","",IF(D39="Enterprise",IFERROR(F39*G39,0),IFERROR(VLOOKUP(D39,อัตราค่าคอม!A5:B8,2,FALSE)*G39,0)))
G40: =IF(D40="","",IF(E40="ต่ออายุ",IFERROR(VLOOKUP(D40,อัตราค่าคอม!A5:E8,5,FALSE),0),IFERROR(VLOOKUP(D40,อัตราค่าคอม!A5:C8,3,FALSE),0))) | H40: =IF(D40="","",IF(D40="Enterprise",IFERROR(F40*G40,0),IFERROR(VLOOKUP(D40,อัตราค่าคอม!A5:B8,2,FALSE)*G40,0)))
G41: =IF(D41="","",IF(E41="ต่ออายุ",IFERROR(VLOOKUP(D41,อัตราค่าคอม!A5:E8,5,FALSE),0),IFERROR(VLOOKUP(D41,อัตราค่าคอม!A5:C8,3,FALSE),0))) | H41: =IF(D41="","",IF(D41="Enterprise",IFERROR(F41*G41,0),IFERROR(VLOOKUP(D41,อัตราค่าคอม!A5:B8,2,FALSE)*G41,0)))
...

Sheet สรุปรายคน
A1: สรุปค่าคอมรายคน — เพิ่มชื่อ Sales ในคอลัมน์ A
A3: Sales | B3: จำนวนดีล | C3: ยอดขายรวม (฿) | D3: ค่าคอมรวม (฿) | E3: ค่าคอมจ่ายแล้ว (฿) | F3: ค่าคอมค้างจ่าย (฿)
A4: MIZTEEN | B4: =COUNTIF(คำนวณรายเดือน!B5:B54,A4) | C4: =SUMIFS(คำนวณรายเดือน!F5:F54,คำนวณรายเดือน!B5:B54,A4,คำนวณรายเดือน!D5:D54,"Enterprise")+SUMPRODUCT((คำนวณรายเดือน!B5:B54=A4)*(คำนวณรายเดือน!D5:D54<>"Enterprise")*IFERROR(VLOOKUP(คำนวณรายเดือน!D5:D54,อัตราค่าคอม!A5:B8,2,FALSE),0)) | D4: =SUMIF(คำนวณรายเดือน!B5:B54,A4,คำนวณรายเดือน!H5:H54) | E4: =SUMIFS(คำนวณรายเดือน!H5:H54,คำนวณรายเดือน!B5:B54,A4,คำนวณรายเดือน!I5:I54,"จ่ายแล้ว") | F4: =D4-E4
A5: OLIVE | B5: =COUNTIF(คำนวณรายเดือน!B5:B54,A5) | C5: =SUMIFS(คำนวณรายเดือน!F5:F54,คำนวณรายเดือน!B5:B54,A5,คำนวณรายเดือน!D5:D54,"Enterprise")+SUMPRODUCT((คำนวณรายเดือน!B5:B54=A5)*(คำนวณรายเดือน!D5:D54<>"Enterprise")*IFERROR(VLOOKUP(คำนวณรายเดือน!D5:D54,อัตราค่าคอม!A5:B8,2,FALSE),0)) | D5: =SUMIF(คำนวณรายเดือน!B5:B54,A5,คำนวณรายเดือน!H5:H54) | E5: =SUMIFS(คำนวณรายเดือน!H5:H54,คำนวณรายเดือน!B5:B54,A5,คำนวณรายเดือน!I5:I54,"จ่ายแล้ว") | F5: =D5-E5
A6: SUPPORT | B6: =COUNTIF(คำนวณรายเดือน!B5:B54,A6) | C6: =SUMIFS(คำนวณรายเดือน!F5:F54,คำนวณรายเดือน!B5:B54,A6,คำนวณรายเดือน!D5:D54,"Enterprise")+SUMPRODUCT((คำนวณรายเดือน!B5:B54=A6)*(คำนวณรายเดือน!D5:D54<>"Enterprise")*IFERROR(VLOOKUP(คำนวณรายเดือน!D5:D54,อัตราค่าคอม!A5:B8,2,FALSE),0)) | D6: =SUMIF(คำนวณรายเดือน!B5:B54,A6,คำนวณรายเดือน!H5:H54) | E6: =SUMIFS(คำนวณรายเดือน!H5:H54,คำนวณรายเดือน!B5:B54,A6,คำนวณรายเดือน!I5:I54,"จ่ายแล้ว") | F6: =D6-E6
A14: รวมทั้งทีม | B14: =SUM(B4:B12) | C14: =SUM(C4:C12) | D14: =SUM(D4:D12) | E14: =SUM(E4:E12) | F14: =SUM(F4:F12)
